<?xml version="1.0" encoding="utf-8"?>
<!-- This URDF was automatically created by SolidWorks to URDF Exporter! Originally created by Stephen Brawner (brawner@gmail.com) 
     Commit Version:   Build Version: 1.6.9305.33219
     For more information, please see http://wiki.ros.org/sw_urdf_exporter -->
<robot
  name="simple_bipedal">
  <link
    name="base_link">
    <inertial>
      <origin
        xyz="3.14816865236183E-18 -0.0233636341691508 5.99607732512132E-17"
        rpy="0 0 0" />
      <mass
        value="10.4073975462643" />
      <inertia
        ixx="0.366615542809238"
        ixy="0.966734798109379E-17"
        ixz="0.761041258947234E-17"
        iyy="0.162745702837988"
        iyz="-0.218052171094121E-16"
        izz="0.270815583070119" />
    </inertial>
    <visual>
      <origin
        xyz="0 0 0"
        rpy="0 0 0" />
      <geometry>
        <mesh
          filename="package://simple_bipedal/meshes/base_link.STL" />
      </geometry>
      <material
        name="">
        <color
          rgba="0.898039215686275 0.917647058823529 0.929411764705882 1" />
      </material>
    </visual>
    <collision>
      <origin
        xyz="0 0 0"
        rpy="0 0 0" />
      <geometry>
        <mesh
          filename="package://simple_bipedal/meshes/base_link.STL" />
      </geometry>
    </collision>
  </link>
  <link
    name="hip_pitch_left_link">
    <inertial>
      <origin
        xyz="2.50382927681168E-08 -5.55111512312578E-17 2.50382927446946E-08"
        rpy="0 0 0" />
      <mass
        value="0.817782778579702" />
      <inertia
        ixx="0.00274609810436168"
        ixy="0.176383028134348E-08"
        ixz="0.513566616479572E-15"
        iyy="0.00285282306584235"
        iyz="-0.176383028106682E-08"
        izz="0.00274609810436168" />
    </inertial>
    <visual>
      <origin
        xyz="0 0 0"
        rpy="0 0 0" />
      <geometry>
        <mesh
          filename="package://simple_bipedal/meshes/hip_pitch_left_link.STL" />
      </geometry>
      <material
        name="">
        <color
          rgba="0.898039215686275 0.917647058823529 0.929411764705882 1" />
      </material>
    </visual>
    <collision>
      <origin
        xyz="0 0 0"
        rpy="0 0 0" />
      <geometry>
        <mesh
          filename="package://simple_bipedal/meshes/hip_pitch_left_link.STL" />
      </geometry>
    </collision>
  </link>
  <joint
    name="hip_pitch_left_joint"
    type="continuous">
    <origin
      xyz="0 -0.355 -0.125"
      rpy="0 0 0" />
    <parent
      link="base_link" />
    <child
      link="hip_pitch_left_link" />
    <axis
      xyz="0 0 1" />
    <limit
      lower="-1.57"
      upper="1.57"
      effort="100.0"
      velocity="10.0" />
  </joint>
  <link
    name="hip_roll_left_link">
    <inertial>
      <origin
        xyz="-8.88594652651202E-19 -0.0742004636472874 -2.77555756156289E-17"
        rpy="0 0 0" />
      <mass
        value="0.612916564770063" />
      <inertia
        ixx="0.00301865314382572"
        ixy="-0.197648441430744E-18"
        ixz="-0.25976824930112E-18"
        iyy="0.00340758392796289"
        iyz="0.120342273549719E-18"
        izz="0.0044385967333728" />
    </inertial>
    <visual>
      <origin
        xyz="0 0 0"
        rpy="0 0 0" />
      <geometry>
        <mesh
          filename="package://simple_bipedal/meshes/hip_roll_left_link.STL" />
      </geometry>
      <material
        name="">
        <color
          rgba="0.898039215686275 0.917647058823529 0.929411764705882 1" />
      </material>
    </visual>
    <collision>
      <origin
        xyz="0 0 0"
        rpy="0 0 0" />
      <geometry>
        <mesh
          filename="package://simple_bipedal/meshes/hip_roll_left_link.STL" />
      </geometry>
    </collision>
  </link>
  <joint
    name="hip_roll_left_joint"
    type="continuous">
    <origin
      xyz="0 0 0"
      rpy="0 0 0" />
    <parent
      link="hip_pitch_left_link" />
    <child
      link="hip_roll_left_link" />
    <axis
      xyz="1 0 0" />
    <limit
      lower="-1.57"
      upper="1.57"
      effort="100.0"
      velocity="10.0" />
  </joint>
  <link
    name="hip_yaw_left_link">
    <inertial>
      <origin
        xyz="-1.51139860408346E-08 -0.163359087286797 1.38777878078145E-17"
        rpy="0 0 0" />
      <mass
        value="1.59288324363201" />
      <inertia
        ixx="0.0158006429792871"
        ixy="0.681537911575121E-09"
        ixz="-0.486680100502339E-08"
        iyy="0.00486950529120668"
        iyz="0.284857007659769E-18"
        izz="0.0155807620289761" />
    </inertial>
    <visual>
      <origin
        xyz="0 0 0"
        rpy="0 0 0" />
      <geometry>
        <mesh
          filename="package://simple_bipedal/meshes/hip_yaw_left_link.STL" />
      </geometry>
      <material
        name="">
        <color
          rgba="0.898039215686275 0.917647058823529 0.929411764705882 1" />
      </material>
    </visual>
    <collision>
      <origin
        xyz="0 0 0"
        rpy="0 0 0" />
      <geometry>
        <mesh
          filename="package://simple_bipedal/meshes/hip_yaw_left_link.STL" />
      </geometry>
    </collision>
  </link>
  <joint
    name="hip_yaw_left_joint"
    type="continuous">
    <origin
      xyz="0 -0.15 0"
      rpy="0 0 0" />
    <parent
      link="hip_roll_left_link" />
    <child
      link="hip_yaw_left_link" />
    <axis
      xyz="0 -1 0" />
    <limit
      lower="-1.57"
      upper="1.57"
      effort="100.0"
      velocity="10.0" />
  </joint>
  <link
    name="knee_pitch_left_link">
    <inertial>
      <origin
        xyz="-2.57657030922869E-08 -0.195112626503353 -2.53453038001616E-08"
        rpy="0 0 0" />
      <mass
        value="1.73220695885815" />
      <inertia
        ixx="0.0243852593261598"
        ixy="0.637172732215568E-08"
        ixz="-0.473538003380343E-08"
        iyy="0.00694508483137373"
        iyz="-0.572266275466994E-08"
        izz="0.0227453959920081" />
    </inertial>
    <visual>
      <origin
        xyz="0 0 0"
        rpy="0 0 0" />
      <geometry>
        <mesh
          filename="package://simple_bipedal/meshes/knee_pitch_left_link.STL" />
      </geometry>
      <material
        name="">
        <color
          rgba="0.898039215686275 0.917647058823529 0.929411764705882 1" />
      </material>
    </visual>
    <collision>
      <origin
        xyz="0 0 0"
        rpy="0 0 0" />
      <geometry>
        <mesh
          filename="package://simple_bipedal/meshes/knee_pitch_left_link.STL" />
      </geometry>
    </collision>
  </link>
  <joint
    name="knee_pitch_left_joint"
    type="continuous">
    <origin
      xyz="0 -0.25 0"
      rpy="0 0 0" />
    <parent
      link="hip_yaw_left_link" />
    <child
      link="knee_pitch_left_link" />
    <axis
      xyz="0 0 1" />
    <limit
      lower="-1.57"
      upper="1.57"
      effort="100.0"
      velocity="10.0" />
  </joint>
  <link
    name="ankle_pitch_left_link">
    <inertial>
      <origin
        xyz="2.18852964426249E-18 -0.141401742541555 -2.77555756156289E-17"
        rpy="0 0 0" />
      <mass
        value="1.33431533790223" />
      <inertia
        ixx="0.0119819082175432"
        ixy="0.356064212644614E-18"
        ixz="-0.857344274603269E-19"
        iyy="0.00616832875211421"
        iyz="-0.153060376016585E-17"
        izz="0.0107284629027132" />
    </inertial>
    <visual>
      <origin
        xyz="0 0 0"
        rpy="0 0 0" />
      <geometry>
        <mesh
          filename="package://simple_bipedal/meshes/ankle_pitch_left_link.STL" />
      </geometry>
      <material
        name="">
        <color
          rgba="0.898039215686275 0.917647058823529 0.929411764705882 1" />
      </material>
    </visual>
    <collision>
      <origin
        xyz="0 0 0"
        rpy="0 0 0" />
      <geometry>
        <mesh
          filename="package://simple_bipedal/meshes/ankle_pitch_left_link.STL" />
      </geometry>
    </collision>
  </link>
  <joint
    name="ankle_pitch_left_joint"
    type="continuous">
    <origin
      xyz="0 -0.3 0"
      rpy="0 0 0" />
    <parent
      link="knee_pitch_left_link" />
    <child
      link="ankle_pitch_left_link" />
    <axis
      xyz="0 0 1" />
    <limit
      lower="-1.57"
      upper="1.57"
      effort="100.0"
      velocity="10.0" />
  </joint>
  <link
    name="ankle_roll_left_link">
    <inertial>
      <origin
        xyz="6.75518732543963E-18 -0.0513144703910333 1.38777878078145E-17"
        rpy="0 0 0" />
      <mass
        value="0.464559018505733" />
      <inertia
        ixx="0.00197277410568368"
        ixy="0.19750314774744E-18"
        ixz="-0.328074232638804E-18"
        iyy="0.00425686282909446"
        iyz="-0.173111382544016E-18"
        izz="0.00457633969523077" />
    </inertial>
    <visual>
      <origin
        xyz="0 0 0"
        rpy="0 0 0" />
      <geometry>
        <mesh
          filename="package://simple_bipedal/meshes/ankle_roll_left_link.STL" />
      </geometry>
      <material
        name="">
        <color
          rgba="0.898039215686275 0.917647058823529 0.929411764705882 1" />
      </material>
    </visual>
    <collision>
      <origin
        xyz="0 0 0"
        rpy="0 0 0" />
      <geometry>
        <mesh
          filename="package://simple_bipedal/meshes/ankle_roll_left_link.STL" />
      </geometry>
    </collision>
  </link>
  <joint
    name="ankle_roll_left_joint"
    type="continuous">
    <origin
      xyz="0 -0.2 0"
      rpy="0 0 0" />
    <parent
      link="ankle_pitch_left_link" />
    <child
      link="ankle_roll_left_link" />
    <axis
      xyz="1 0 0" />
    <limit
      lower="-1.57"
      upper="1.57"
      effort="100.0"
      velocity="10.0" />
  </joint>
  <link
    name="hip_pitch_right_link">
    <inertial>
      <origin
        xyz="2.50382927761668E-08 5.55111512312578E-17 2.50382927724502E-08"
        rpy="0 0 0" />
      <mass
        value="0.817782778579702" />
      <inertia
        ixx="0.00274609810436168"
        ixy="0.176383028094622E-08"
        ixz="0.513166804588344E-15"
        iyy="0.00285282306584235"
        iyz="-0.176383028105973E-08"
        izz="0.00274609810436168" />
    </inertial>
    <visual>
      <origin
        xyz="0 0 0"
        rpy="0 0 0" />
      <geometry>
        <mesh
          filename="package://simple_bipedal/meshes/hip_pitch_right_link.STL" />
      </geometry>
      <material
        name="">
        <color
          rgba="0.898039215686275 0.917647058823529 0.929411764705882 1" />
      </material>
    </visual>
    <collision>
      <origin
        xyz="0 0 0"
        rpy="0 0 0" />
      <geometry>
        <mesh
          filename="package://simple_bipedal/meshes/hip_pitch_right_link.STL" />
      </geometry>
    </collision>
  </link>
  <joint
    name="hip_pitch_right_joint"
    type="continuous">
    <origin
      xyz="0 -0.355 0.125"
      rpy="0 0 0" />
    <parent
      link="base_link" />
    <child
      link="hip_pitch_right_link" />
    <axis
      xyz="0 0 1" />
    <limit
      lower="-1.57"
      upper="1.57"
      effort="100.0"
      velocity="10.0" />
  </joint>
  <link
    name="hip_roll_right_link">
    <inertial>
      <origin
        xyz="-7.36727495988482E-18 -0.0742004636472874 0"
        rpy="0 0 0" />
      <mass
        value="0.612916564770063" />
      <inertia
        ixx="0.00301865314382572"
        ixy="-0.165758435059659E-18"
        ixz="-0.229671192274964E-18"
        iyy="0.00340758392796289"
        iyz="0.165850481115776E-18"
        izz="0.0044385967333728" />
    </inertial>
    <visual>
      <origin
        xyz="0 0 0"
        rpy="0 0 0" />
      <geometry>
        <mesh
          filename="package://simple_bipedal/meshes/hip_roll_right_link.STL" />
      </geometry>
      <material
        name="">
        <color
          rgba="0.898039215686275 0.917647058823529 0.929411764705882 1" />
      </material>
    </visual>
    <collision>
      <origin
        xyz="0 0 0"
        rpy="0 0 0" />
      <geometry>
        <mesh
          filename="package://simple_bipedal/meshes/hip_roll_right_link.STL" />
      </geometry>
    </collision>
  </link>
  <joint
    name="hip_roll_right_joint"
    type="continuous">
    <origin
      xyz="0 0 0"
      rpy="0 0 0" />
    <parent
      link="hip_pitch_right_link" />
    <child
      link="hip_roll_right_link" />
    <axis
      xyz="1 0 0" />
    <limit
      lower="-1.57"
      upper="1.57"
      effort="100.0"
      velocity="10.0" />
  </joint>
  <link
    name="hip_yaw_right_link">
    <inertial>
      <origin
        xyz="-1.51139860422597E-08 -0.163359087286797 0"
        rpy="0 0 0" />
      <mass
        value="1.59288324363201" />
      <inertia
        ixx="0.0158006429792871"
        ixy="0.681537911357161E-09"
        ixz="-0.486680100505176E-08"
        iyy="0.00486950529120669"
        iyz="0.216392355495271E-18"
        izz="0.0155807620289761" />
    </inertial>
    <visual>
      <origin
        xyz="0 0 0"
        rpy="0 0 0" />
      <geometry>
        <mesh
          filename="package://simple_bipedal/meshes/hip_yaw_right_link.STL" />
      </geometry>
      <material
        name="">
        <color
          rgba="0.898039215686275 0.917647058823529 0.929411764705882 1" />
      </material>
    </visual>
    <collision>
      <origin
        xyz="0 0 0"
        rpy="0 0 0" />
      <geometry>
        <mesh
          filename="package://simple_bipedal/meshes/hip_yaw_right_link.STL" />
      </geometry>
    </collision>
  </link>
  <joint
    name="hip_yaw_right_joint"
    type="continuous">
    <origin
      xyz="0 -0.15 0"
      rpy="0 0 0" />
    <parent
      link="hip_roll_right_link" />
    <child
      link="hip_yaw_right_link" />
    <axis
      xyz="0 -1 0" />
    <limit
      lower="-1.57"
      upper="1.57"
      effort="100.0"
      velocity="10.0" />
  </joint>
  <link
    name="knee_pitch_right_link">
    <inertial>
      <origin
        xyz="-2.57657030843257E-08 -0.195112626503353 -2.53453038001616E-08"
        rpy="0 0 0" />
      <mass
        value="1.73220695885815" />
      <inertia
        ixx="0.0243852593261598"
        ixy="0.637172732266414E-08"
        ixz="-0.473538003406399E-08"
        iyy="0.00694508483137373"
        iyz="-0.572266275207433E-08"
        izz="0.0227453959920081" />
    </inertial>
    <visual>
      <origin
        xyz="0 0 0"
        rpy="0 0 0" />
      <geometry>
        <mesh
          filename="package://simple_bipedal/meshes/knee_pitch_right_link.STL" />
      </geometry>
      <material
        name="">
        <color
          rgba="0.898039215686275 0.917647058823529 0.929411764705882 1" />
      </material>
    </visual>
    <collision>
      <origin
        xyz="0 0 0"
        rpy="0 0 0" />
      <geometry>
        <mesh
          filename="package://simple_bipedal/meshes/knee_pitch_right_link.STL" />
      </geometry>
    </collision>
  </link>
  <joint
    name="knee_pitch_right_joint"
    type="continuous">
    <origin
      xyz="0 -0.25 0"
      rpy="0 0 0" />
    <parent
      link="hip_yaw_right_link" />
    <child
      link="knee_pitch_right_link" />
    <axis
      xyz="0 0 1" />
    <limit
      lower="-1.57"
      upper="1.57"
      effort="100.0"
      velocity="10.0" />
  </joint>
  <link
    name="ankle_pitch_right_link">
    <inertial>
      <origin
        xyz="-5.33523512629707E-19 -0.141401742541555 -1.38777878078145E-17"
        rpy="0 0 0" />
      <mass
        value="1.33431533790223" />
      <inertia
        ixx="0.0119819082175432"
        ixy="0.449687333526178E-18"
        ixz="-0.573588237273077E-19"
        iyy="0.00616832875211421"
        iyz="0.37107417489958E-19"
        izz="0.0107284629027132" />
    </inertial>
    <visual>
      <origin
        xyz="0 0 0"
        rpy="0 0 0" />
      <geometry>
        <mesh
          filename="package://simple_bipedal/meshes/ankle_pitch_right_link.STL" />
      </geometry>
      <material
        name="">
        <color
          rgba="0.898039215686275 0.917647058823529 0.929411764705882 1" />
      </material>
    </visual>
    <collision>
      <origin
        xyz="0 0 0"
        rpy="0 0 0" />
      <geometry>
        <mesh
          filename="package://simple_bipedal/meshes/ankle_pitch_right_link.STL" />
      </geometry>
    </collision>
  </link>
  <joint
    name="ankle_pitch_right_joint"
    type="continuous">
    <origin
      xyz="0 -0.3 0"
      rpy="0 0 0" />
    <parent
      link="knee_pitch_right_link" />
    <child
      link="ankle_pitch_right_link" />
    <axis
      xyz="0 0 1" />
    <limit
      lower="-1.57"
      upper="1.57"
      effort="100.0"
      velocity="10.0" />
  </joint>
  <link
    name="ankle_roll_right_link">
    <inertial>
      <origin
        xyz="3.0417250453847E-18 -0.0513144703910333 -1.38777878078145E-17"
        rpy="0 0 0" />
      <mass
        value="0.464559018505733" />
      <inertia
        ixx="0.00197277410568368"
        ixy="0.237138749549365E-18"
        ixz="-0.157816614955685E-18"
        iyy="0.00425686282909446"
        iyz="-0.354638334121962E-18"
        izz="0.00457633969523077" />
    </inertial>
    <visual>
      <origin
        xyz="0 0 0"
        rpy="0 0 0" />
      <geometry>
        <mesh
          filename="package://simple_bipedal/meshes/ankle_roll_right_link.STL" />
      </geometry>
      <material
        name="">
        <color
          rgba="0.898039215686275 0.917647058823529 0.929411764705882 1" />
      </material>
    </visual>
    <collision>
      <origin
        xyz="0 0 0"
        rpy="0 0 0" />
      <geometry>
        <mesh
          filename="package://simple_bipedal/meshes/ankle_roll_right_link.STL" />
      </geometry>
    </collision>
  </link>
  <joint
    name="ankle_roll_right_joint"
    type="continuous">
    <origin
      xyz="0 -0.2 0"
      rpy="0 0 0" />
    <parent
      link="ankle_pitch_right_link" />
    <child
      link="ankle_roll_right_link" />
    <axis
      xyz="1 0 0" />
    <limit
      lower="-1.57"
      upper="1.57"
      effort="100.0"
      velocity="10.0" />
  </joint>
</robot>