<?xml version="1.0" encoding="utf-8"?>
<!-- This URDF was automatically created by SolidWorks to URDF Exporter! Originally created by Stephen Brawner (brawner@gmail.com) 
     Commit Version:   Build Version: 1.6.9305.33219
     For more information, please see http://wiki.ros.org/sw_urdf_exporter -->
<robot
  name="simple_bipedal">
  <link
    name="base_link">
    <inertial>
      <origin
        xyz="2.3957E-18 -0.016415 6.1719E-17"
        rpy="0 0 0" />
      <mass
        value="10.167" />
      <inertia
        ixx="0.34448"
        ixy="6.8915E-18"
        ixz="5.6161E-18"
        iyy="0.16165"
        iyz="1.8865E-18"
        izz="0.24799" />
    </inertial>
    <visual>
      <origin
        xyz="0 0 0"
        rpy="0 0 0" />
      <geometry>
        <mesh
          filename="package://simple_bipedal/meshes/base_link.STL" />
      </geometry>
      <material
        name="">
        <color
          rgba="0.86667 0.9098 1 1" />
      </material>
    </visual>
    <collision>
      <origin
        xyz="0 0 0"
        rpy="0 0 0" />
      <geometry>
        <mesh
          filename="package://simple_bipedal/meshes/base_link.STL" />
      </geometry>
    </collision>
  </link>
  <link
    name="hip_pitch_left_link">
    <inertial>
      <origin
        xyz="2.33690732279828E-08 0 2.33690732043268E-08"
        rpy="0 0 0" />
      <mass
        value="0.664887687236356" />
      <inertia
        ixx="0.00194491189054185"
        ixy="1.24922502997283E-09"
        ixz="3.63079895867531E-16"
        iyy="0.00202049937456935"
        iyz="-1.24922502969971E-09"
        izz="0.00194491189054185" />
    </inertial>
    <visual>
      <origin
        xyz="0 0 0"
        rpy="0 0 0" />
      <geometry>
        <mesh
          filename="package://simple_bipedal/meshes/hip_pitch_left_link.STL" />
      </geometry>
      <material
        name="">
        <color
          rgba="0.866666666666667 0.909803921568627 1 1" />
      </material>
    </visual>
    <collision>
      <origin
        xyz="0 0 0"
        rpy="0 0 0" />
      <geometry>
        <mesh
          filename="package://simple_bipedal/meshes/hip_pitch_left_link.STL" />
      </geometry>
    </collision>
  </link>
  <joint
    name="hip_pitch_left_joint"
    type="continuous">
    <origin
      xyz="0 -0.355 -0.125"
      rpy="0 0 0" />
    <parent
      link="base_link" />
    <child
      link="hip_pitch_left_link" />
    <axis
      xyz="0 0 1" />
    <limit
      lower="-1.57"
      upper="1.57"
      effort="100"
      velocity="10" />
  </joint>
  <link
    name="hip_roll_left_link">
    <inertial>
      <origin
        xyz="5.47988322332102E-18 -0.071448992050803 0"
        rpy="0 0 0" />
      <mass
        value="0.530800065725118" />
      <inertia
        ixx="0.00238182060955742"
        ixy="1.33587179200789E-20"
        ixz="-1.93986095976325E-19"
        iyy="0.00288416659073163"
        iyz="-6.73805290334419E-20"
        izz="0.00375103770592918" />
    </inertial>
    <visual>
      <origin
        xyz="0 0 0"
        rpy="0 0 0" />
      <geometry>
        <mesh
          filename="package://simple_bipedal/meshes/hip_roll_left_link.STL" />
      </geometry>
      <material
        name="">
        <color
          rgba="0.866666666666667 0.909803921568627 1 1" />
      </material>
    </visual>
    <collision>
      <origin
        xyz="0 0 0"
        rpy="0 0 0" />
      <geometry>
        <mesh
          filename="package://simple_bipedal/meshes/hip_roll_left_link.STL" />
      </geometry>
    </collision>
  </link>
  <joint
    name="hip_roll_left_joint"
    type="continuous">
    <origin
      xyz="0 0 0"
      rpy="0 0 0" />
    <parent
      link="hip_pitch_left_link" />
    <child
      link="hip_roll_left_link" />
    <axis
      xyz="1 0 0" />
    <limit
      lower="-1.57"
      upper="1.57"
      effort="100"
      velocity="10" />
  </joint>
  <link
    name="hip_yaw_left_link">
    <inertial>
      <origin
        xyz="-1.53307894851172E-08 -0.161028143140512 0"
        rpy="0 0 0" />
      <mass
        value="1.36383246641991" />
      <inertia
        ixx="0.0129648379825961"
        ixy="4.73949257847294E-10"
        ixz="-3.64916490298114E-09"
        iyy="0.00361726436697802"
        iyz="-1.2642707667673E-19"
        izz="0.0128091054286981" />
    </inertial>
    <visual>
      <origin
        xyz="0 0 0"
        rpy="0 0 0" />
      <geometry>
        <mesh
          filename="package://simple_bipedal/meshes/hip_yaw_left_link.STL" />
      </geometry>
      <material
        name="">
        <color
          rgba="0.866666666666667 0.909803921568627 1 1" />
      </material>
    </visual>
    <collision>
      <origin
        xyz="0 0 0"
        rpy="0 0 0" />
      <geometry>
        <mesh
          filename="package://simple_bipedal/meshes/hip_yaw_left_link.STL" />
      </geometry>
    </collision>
  </link>
  <joint
    name="hip_yaw_left_joint"
    type="continuous">
    <origin
      xyz="0 -0.15 0"
      rpy="0 0 0" />
    <parent
      link="hip_roll_left_link" />
    <child
      link="hip_yaw_left_link" />
    <axis
      xyz="0 -1 0" />
    <limit
      lower="-1.57"
      upper="1.57"
      effort="100"
      velocity="10" />
  </joint>
  <link
    name="knee_pitch_left_link">
    <inertial>
      <origin
        xyz="-4.5329426770206E-08 -0.1913342221555 -5.74365988936787E-08"
        rpy="0 0 0" />
      <mass
        value="1.50270730941549" />
      <inertia
        ixx="0.0206480149866074"
        ixy="5.19726298765753E-09"
        ixz="-1.0654232083862E-09"
        iyy="0.00554119545375214"
        iyz="-5.77368067223139E-09"
        izz="0.0191230395144735" />
    </inertial>
    <visual>
      <origin
        xyz="0 0 0"
        rpy="0 0 0" />
      <geometry>
        <mesh
          filename="package://simple_bipedal/meshes/knee_pitch_left_link.STL" />
      </geometry>
      <material
        name="">
        <color
          rgba="0.866666666666667 0.909803921568627 1 1" />
      </material>
    </visual>
    <collision>
      <origin
        xyz="0 0 0"
        rpy="0 0 0" />
      <geometry>
        <mesh
          filename="package://simple_bipedal/meshes/knee_pitch_left_link.STL" />
      </geometry>
    </collision>
  </link>
  <joint
    name="knee_pitch_left_joint"
    type="continuous">
    <origin
      xyz="0 -0.25 0"
      rpy="0 0 0" />
    <parent
      link="hip_yaw_left_link" />
    <child
      link="knee_pitch_left_link" />
    <axis
      xyz="0 0 1" />
    <limit
      lower="-1.57"
      upper="1.57"
      effort="100"
      velocity="10" />
  </joint>
  <link
    name="ankle_pitch_left_link">
    <inertial>
      <origin
        xyz="1.12299858547934E-17 -0.138293351959195 -2.77555756156289E-17"
        rpy="0 0 0" />
      <mass
        value="1.15921855254247" />
      <inertia
        ixx="0.0100513482421227"
        ixy="-1.30273512224744E-19"
        ixz="3.97825964336926E-20"
        iyy="0.00497069222002865"
        iyz="-6.37423018329792E-19"
        izz="0.00880005281567877" />
    </inertial>
    <visual>
      <origin
        xyz="0 0 0"
        rpy="0 0 0" />
      <geometry>
        <mesh
          filename="package://simple_bipedal/meshes/ankle_pitch_left_link.STL" />
      </geometry>
      <material
        name="">
        <color
          rgba="0.866666666666667 0.909803921568627 1 1" />
      </material>
    </visual>
    <collision>
      <origin
        xyz="0 0 0"
        rpy="0 0 0" />
      <geometry>
        <mesh
          filename="package://simple_bipedal/meshes/ankle_pitch_left_link.STL" />
      </geometry>
    </collision>
  </link>
  <joint
    name="ankle_pitch_left_joint"
    type="continuous">
    <origin
      xyz="0 -0.3 0"
      rpy="0 0 0" />
    <parent
      link="knee_pitch_left_link" />
    <child
      link="ankle_pitch_left_link" />
    <axis
      xyz="0 0 1" />
    <limit
      lower="-1.57"
      upper="1.57"
      effort="100"
      velocity="10" />
  </joint>
  <link
    name="ankle_roll_left_link">
    <inertial>
      <origin
        xyz="-4.51820833094692E-18 -0.0528696020875221 0"
        rpy="0 0 0" />
      <mass
        value="0.427694789453883" />
      <inertia
        ixx="0.00165757423871352"
        ixy="-1.16263618462654E-19"
        ixz="5.92622937304524E-20"
        iyy="0.00382363159720044"
        iyz="1.61518563669245E-19"
        izz="0.00415145333508528" />
    </inertial>
    <visual>
      <origin
        xyz="0 0 0"
        rpy="0 0 0" />
      <geometry>
        <mesh
          filename="package://simple_bipedal/meshes/ankle_roll_left_link.STL" />
      </geometry>
      <material
        name="">
        <color
          rgba="0.866666666666667 0.909803921568627 1 1" />
      </material>
    </visual>
    <collision>
      <origin
        xyz="0 0 0"
        rpy="0 0 0" />
      <geometry>
        <mesh
          filename="package://simple_bipedal/meshes/ankle_roll_left_link.STL" />
      </geometry>
    </collision>
  </link>
  <joint
    name="ankle_roll_left_joint"
    type="continuous">
    <origin
      xyz="0 -0.2 0"
      rpy="0 0 0" />
    <parent
      link="ankle_pitch_left_link" />
    <child
      link="ankle_roll_left_link" />
    <axis
      xyz="1 0 0" />
    <limit
      lower="-1.57"
      upper="1.57"
      effort="100"
      velocity="10" />
  </joint>
  <link
    name="hip_pitch_right_link">
    <inertial>
      <origin
        xyz="2.33690732320798E-08 0 2.33690732598379E-08"
        rpy="0 0 0" />
      <mass
        value="0.664887687236356" />
      <inertia
        ixx="0.00194491189054185"
        ixy="1.24922502997992E-09"
        ixz="3.6295929978906E-16"
        iyy="0.00202049937456935"
        iyz="-1.24922503017678E-09"
        izz="0.00194491189054185" />
    </inertial>
    <visual>
      <origin
        xyz="0 0 0"
        rpy="0 0 0" />
      <geometry>
        <mesh
          filename="package://simple_bipedal/meshes/hip_pitch_right_link.STL" />
      </geometry>
      <material
        name="">
        <color
          rgba="0.866666666666667 0.909803921568627 1 1" />
      </material>
    </visual>
    <collision>
      <origin
        xyz="0 0 0"
        rpy="0 0 0" />
      <geometry>
        <mesh
          filename="package://simple_bipedal/meshes/hip_pitch_right_link.STL" />
      </geometry>
    </collision>
  </link>
  <joint
    name="hip_pitch_right_joint"
    type="continuous">
    <origin
      xyz="0 -0.355 0.125"
      rpy="0 0 0" />
    <parent
      link="base_link" />
    <child
      link="hip_pitch_right_link" />
    <axis
      xyz="0 0 1" />
    <limit
      lower="-1.57"
      upper="1.57"
      effort="100"
      velocity="10" />
  </joint>
  <link
    name="hip_roll_right_link">
    <inertial>
      <origin
        xyz="2.04895003790135E-18 -0.071448992050803 0"
        rpy="0 0 0" />
      <mass
        value="0.530800065725118" />
      <inertia
        ixx="0.00238182060955742"
        ixy="-2.32658203747703E-20"
        ixz="-1.93986095976325E-19"
        iyy="0.00288416659073163"
        iyz="-8.41398356667943E-20"
        izz="0.00375103770592918" />
    </inertial>
    <visual>
      <origin
        xyz="0 0 0"
        rpy="0 0 0" />
      <geometry>
        <mesh
          filename="package://simple_bipedal/meshes/hip_roll_right_link.STL" />
      </geometry>
      <material
        name="">
        <color
          rgba="0.866666666666667 0.909803921568627 1 1" />
      </material>
    </visual>
    <collision>
      <origin
        xyz="0 0 0"
        rpy="0 0 0" />
      <geometry>
        <mesh
          filename="package://simple_bipedal/meshes/hip_roll_right_link.STL" />
      </geometry>
    </collision>
  </link>
  <joint
    name="hip_roll_right_joint"
    type="continuous">
    <origin
      xyz="0 0 0"
      rpy="0 0 0" />
    <parent
      link="hip_pitch_right_link" />
    <child
      link="hip_roll_right_link" />
    <axis
      xyz="1 0 0" />
    <limit
      lower="-1.57"
      upper="1.57"
      effort="100"
      velocity="10" />
  </joint>
  <link
    name="hip_yaw_right_link">
    <inertial>
      <origin
        xyz="-1.53307894836862E-08 -0.161028143140512 0"
        rpy="0 0 0" />
      <mass
        value="1.36383246641991" />
      <inertia
        ixx="0.0129648379825961"
        ixy="4.7394925799234E-10"
        ixz="-3.64916490297582E-09"
        iyy="0.00361726436697802"
        iyz="3.0596396483239E-21"
        izz="0.0128091054286981" />
    </inertial>
    <visual>
      <origin
        xyz="0 0 0"
        rpy="0 0 0" />
      <geometry>
        <mesh
          filename="package://simple_bipedal/meshes/hip_yaw_right_link.STL" />
      </geometry>
      <material
        name="">
        <color
          rgba="0.866666666666667 0.909803921568627 1 1" />
      </material>
    </visual>
    <collision>
      <origin
        xyz="0 0 0"
        rpy="0 0 0" />
      <geometry>
        <mesh
          filename="package://simple_bipedal/meshes/hip_yaw_right_link.STL" />
      </geometry>
    </collision>
  </link>
  <joint
    name="hip_yaw_right_joint"
    type="continuous">
    <origin
      xyz="0 -0.15 0"
      rpy="0 0 0" />
    <parent
      link="hip_roll_right_link" />
    <child
      link="hip_yaw_right_link" />
    <axis
      xyz="0 -1 0" />
    <limit
      lower="-1.57"
      upper="1.57"
      effort="100"
      velocity="10" />
  </joint>
  <link
    name="knee_pitch_right_link">
    <inertial>
      <origin
        xyz="-4.53294267741714E-08 -0.1913342221555 -5.74365988798009E-08"
        rpy="0 0 0" />
      <mass
        value="1.50270730941549" />
      <inertia
        ixx="0.0206480149866074"
        ixy="5.19726298721573E-09"
        ixz="-1.06542320821968E-09"
        iyy="0.00554119545375214"
        iyz="-5.77368067040042E-09"
        izz="0.0191230395144735" />
    </inertial>
    <visual>
      <origin
        xyz="0 0 0"
        rpy="0 0 0" />
      <geometry>
        <mesh
          filename="package://simple_bipedal/meshes/knee_pitch_right_link.STL" />
      </geometry>
      <material
        name="">
        <color
          rgba="0.866666666666667 0.909803921568627 1 1" />
      </material>
    </visual>
    <collision>
      <origin
        xyz="0 0 0"
        rpy="0 0 0" />
      <geometry>
        <mesh
          filename="package://simple_bipedal/meshes/knee_pitch_right_link.STL" />
      </geometry>
    </collision>
  </link>
  <joint
    name="knee_pitch_right_joint"
    type="continuous">
    <origin
      xyz="0 -0.25 0"
      rpy="0 0 0" />
    <parent
      link="hip_yaw_right_link" />
    <child
      link="knee_pitch_right_link" />
    <axis
      xyz="0 0 1" />
    <limit
      lower="-1.57"
      upper="1.57"
      effort="100"
      velocity="10" />
  </joint>
  <link
    name="ankle_pitch_right_link">
    <inertial>
      <origin
        xyz="1.12299858547934E-17 -0.138293351959195 -2.77555756156289E-17"
        rpy="0 0 0" />
      <mass
        value="1.15921855254247" />
      <inertia
        ixx="0.0100513482421227"
        ixy="-1.30273512224744E-19"
        ixz="5.70917147108342E-20"
        iyy="0.00497069222002865"
        iyz="-4.44916813926276E-20"
        izz="0.00880005281567877" />
    </inertial>
    <visual>
      <origin
        xyz="0 0 0"
        rpy="0 0 0" />
      <geometry>
        <mesh
          filename="package://simple_bipedal/meshes/ankle_pitch_right_link.STL" />
      </geometry>
      <material
        name="">
        <color
          rgba="0.866666666666667 0.909803921568627 1 1" />
      </material>
    </visual>
    <collision>
      <origin
        xyz="0 0 0"
        rpy="0 0 0" />
      <geometry>
        <mesh
          filename="package://simple_bipedal/meshes/ankle_pitch_right_link.STL" />
      </geometry>
    </collision>
  </link>
  <joint
    name="ankle_pitch_right_joint"
    type="continuous">
    <origin
      xyz="0 -0.3 0"
      rpy="0 0 0" />
    <parent
      link="knee_pitch_right_link" />
    <child
      link="ankle_pitch_right_link" />
    <axis
      xyz="0 0 1" />
    <limit
      lower="-1.57"
      upper="1.57"
      effort="100"
      velocity="10" />
  </joint>
  <link
    name="ankle_roll_right_link">
    <inertial>
      <origin
        xyz="7.6785E-18 -0.05287 -2.7756E-17"
        rpy="0 0 0" />
      <mass
        value="0.42769" />
      <inertia
        ixx="0.0016576"
        ixy="1.6559E-20"
        ixz="2.1793E-19"
        iyy="0.0038236"
        iyz="5.8843E-20"
        izz="0.0041515" />
    </inertial>
    <visual>
      <origin
        xyz="0 0 0"
        rpy="0 0 0" />
      <geometry>
        <mesh
          filename="package://simple_bipedal/meshes/ankle_roll_right_link.STL" />
      </geometry>
      <material
        name="">
        <color
          rgba="0.86667 0.9098 1 1" />
      </material>
    </visual>
    <collision>
      <origin
        xyz="0 0 0"
        rpy="0 0 0" />
      <geometry>
        <mesh
          filename="package://simple_bipedal/meshes/ankle_roll_right_link.STL" />
      </geometry>
    </collision>
  </link>
  <joint
    name="ankle_roll_right_joint"
    type="continuous">
    <origin
      xyz="0 -0.2 0"
      rpy="0 0 0" />
    <parent
      link="ankle_pitch_right_link" />
    <child
      link="ankle_roll_right_link" />
    <axis
      xyz="1 0 0" />
    <limit
      lower="-1.57"
      upper="1.57"
      effort="100"
      velocity="10" />
  </joint>
</robot>